2023-03-28 14:10:54,759 (71903/MainThread) pgcli.main INFO - Default pager found in PAGER environment variable: "less"
2023-03-28 14:10:54,791 (71903/MainThread) pgcli.main ERROR - traceback: 'Traceback (most recent call last):\n  File "/nix/store/wpq8iw12hx7xsblnqpqg7ihaysw73mcw-python3.10-pgcli-3.5.0/lib/python3.10/site-packages/pgcli/main.py", line 640, in connect\n    raise e\n  File "/nix/store/wpq8iw12hx7xsblnqpqg7ihaysw73mcw-python3.10-pgcli-3.5.0/lib/python3.10/site-packages/pgcli/main.py", line 627, in connect\n    pgexecute = PGExecute(database, user, passwd, host, port, dsn, **kwargs)\n  File "/nix/store/wpq8iw12hx7xsblnqpqg7ihaysw73mcw-python3.10-pgcli-3.5.0/lib/python3.10/site-packages/pgcli/pgexecute.py", line 161, in __init__\n    self.connect(database, user, password, host, port, dsn, **kwargs)\n  File "/nix/store/wpq8iw12hx7xsblnqpqg7ihaysw73mcw-python3.10-pgcli-3.5.0/lib/python3.10/site-packages/pgcli/pgexecute.py", line 207, in connect\n    conn = psycopg.connect(conn_info)\n  File "/nix/store/cxfxzqrs01khsh6a2nlprfdikidnnffz-python3.10-psycopg-3.1.8/lib/python3.10/site-packages/psycopg/connection.py", line 728, in connect\n    raise ex.with_traceback(None)\npsycopg.OperationalError: connection is bad: No such file or directory\n\tIs the server running locally and accepting connections on that socket?\n'
2023-03-28 14:11:19,272 (71941/MainThread) pgcli.main INFO - Default pager found in PAGER environment variable: "less"
2023-03-28 14:11:19,292 (71941/MainThread) pgcli.main ERROR - traceback: 'Traceback (most recent call last):\n  File "/nix/store/wpq8iw12hx7xsblnqpqg7ihaysw73mcw-python3.10-pgcli-3.5.0/lib/python3.10/site-packages/pgcli/main.py", line 640, in connect\n    raise e\n  File "/nix/store/wpq8iw12hx7xsblnqpqg7ihaysw73mcw-python3.10-pgcli-3.5.0/lib/python3.10/site-packages/pgcli/main.py", line 627, in connect\n    pgexecute = PGExecute(database, user, passwd, host, port, dsn, **kwargs)\n  File "/nix/store/wpq8iw12hx7xsblnqpqg7ihaysw73mcw-python3.10-pgcli-3.5.0/lib/python3.10/site-packages/pgcli/pgexecute.py", line 161, in __init__\n    self.connect(database, user, password, host, port, dsn, **kwargs)\n  File "/nix/store/wpq8iw12hx7xsblnqpqg7ihaysw73mcw-python3.10-pgcli-3.5.0/lib/python3.10/site-packages/pgcli/pgexecute.py", line 207, in connect\n    conn = psycopg.connect(conn_info)\n  File "/nix/store/cxfxzqrs01khsh6a2nlprfdikidnnffz-python3.10-psycopg-3.1.8/lib/python3.10/site-packages/psycopg/connection.py", line 728, in connect\n    raise ex.with_traceback(None)\npsycopg.OperationalError: connection is bad: No such file or directory\n\tIs the server running locally and accepting connections on that socket?\n'
2023-03-28 14:11:33,544 (71981/MainThread) pgcli.main INFO - Default pager found in PAGER environment variable: "less"
2023-03-28 14:11:33,564 (71981/MainThread) pgcli.main ERROR - traceback: 'Traceback (most recent call last):\n  File "/nix/store/wpq8iw12hx7xsblnqpqg7ihaysw73mcw-python3.10-pgcli-3.5.0/lib/python3.10/site-packages/pgcli/main.py", line 640, in connect\n    raise e\n  File "/nix/store/wpq8iw12hx7xsblnqpqg7ihaysw73mcw-python3.10-pgcli-3.5.0/lib/python3.10/site-packages/pgcli/main.py", line 627, in connect\n    pgexecute = PGExecute(database, user, passwd, host, port, dsn, **kwargs)\n  File "/nix/store/wpq8iw12hx7xsblnqpqg7ihaysw73mcw-python3.10-pgcli-3.5.0/lib/python3.10/site-packages/pgcli/pgexecute.py", line 161, in __init__\n    self.connect(database, user, password, host, port, dsn, **kwargs)\n  File "/nix/store/wpq8iw12hx7xsblnqpqg7ihaysw73mcw-python3.10-pgcli-3.5.0/lib/python3.10/site-packages/pgcli/pgexecute.py", line 207, in connect\n    conn = psycopg.connect(conn_info)\n  File "/nix/store/cxfxzqrs01khsh6a2nlprfdikidnnffz-python3.10-psycopg-3.1.8/lib/python3.10/site-packages/psycopg/connection.py", line 728, in connect\n    raise ex.with_traceback(None)\npsycopg.OperationalError: connection is bad: No such file or directory\n\tIs the server running locally and accepting connections on that socket?\n'
2023-03-28 14:11:45,511 (72017/MainThread) pgcli.main INFO - Default pager found in PAGER environment variable: "less"
2023-03-28 14:11:45,530 (72017/MainThread) pgcli.main ERROR - traceback: 'Traceback (most recent call last):\n  File "/nix/store/wpq8iw12hx7xsblnqpqg7ihaysw73mcw-python3.10-pgcli-3.5.0/lib/python3.10/site-packages/pgcli/main.py", line 640, in connect\n    raise e\n  File "/nix/store/wpq8iw12hx7xsblnqpqg7ihaysw73mcw-python3.10-pgcli-3.5.0/lib/python3.10/site-packages/pgcli/main.py", line 627, in connect\n    pgexecute = PGExecute(database, user, passwd, host, port, dsn, **kwargs)\n  File "/nix/store/wpq8iw12hx7xsblnqpqg7ihaysw73mcw-python3.10-pgcli-3.5.0/lib/python3.10/site-packages/pgcli/pgexecute.py", line 161, in __init__\n    self.connect(database, user, password, host, port, dsn, **kwargs)\n  File "/nix/store/wpq8iw12hx7xsblnqpqg7ihaysw73mcw-python3.10-pgcli-3.5.0/lib/python3.10/site-packages/pgcli/pgexecute.py", line 207, in connect\n    conn = psycopg.connect(conn_info)\n  File "/nix/store/cxfxzqrs01khsh6a2nlprfdikidnnffz-python3.10-psycopg-3.1.8/lib/python3.10/site-packages/psycopg/connection.py", line 728, in connect\n    raise ex.with_traceback(None)\npsycopg.OperationalError: connection is bad: No such file or directory\n\tIs the server running locally and accepting connections on that socket?\n'
2023-03-28 14:11:54,035 (72039/MainThread) pgcli.main INFO - Default pager found in PAGER environment variable: "less"
2023-03-28 14:11:58,050 (72039/MainThread) pgcli.main ERROR - traceback: 'Traceback (most recent call last):\n  File "/nix/store/wpq8iw12hx7xsblnqpqg7ihaysw73mcw-python3.10-pgcli-3.5.0/lib/python3.10/site-packages/pgcli/main.py", line 627, in connect\n    pgexecute = PGExecute(database, user, passwd, host, port, dsn, **kwargs)\n  File "/nix/store/wpq8iw12hx7xsblnqpqg7ihaysw73mcw-python3.10-pgcli-3.5.0/lib/python3.10/site-packages/pgcli/pgexecute.py", line 161, in __init__\n    self.connect(database, user, password, host, port, dsn, **kwargs)\n  File "/nix/store/wpq8iw12hx7xsblnqpqg7ihaysw73mcw-python3.10-pgcli-3.5.0/lib/python3.10/site-packages/pgcli/pgexecute.py", line 207, in connect\n    conn = psycopg.connect(conn_info)\n  File "/nix/store/cxfxzqrs01khsh6a2nlprfdikidnnffz-python3.10-psycopg-3.1.8/lib/python3.10/site-packages/psycopg/connection.py", line 728, in connect\n    raise ex.with_traceback(None)\npsycopg.OperationalError: connection failed: :1), port 7878 failed: fe_sendauth: no password supplied\n\nDuring handling of the above exception, another exception occurred:\n\nTraceback (most recent call last):\n  File "/nix/store/wpq8iw12hx7xsblnqpqg7ihaysw73mcw-python3.10-pgcli-3.5.0/lib/python3.10/site-packages/pgcli/main.py", line 636, in connect\n    pgexecute = PGExecute(\n  File "/nix/store/wpq8iw12hx7xsblnqpqg7ihaysw73mcw-python3.10-pgcli-3.5.0/lib/python3.10/site-packages/pgcli/pgexecute.py", line 161, in __init__\n    self.connect(database, user, password, host, port, dsn, **kwargs)\n  File "/nix/store/wpq8iw12hx7xsblnqpqg7ihaysw73mcw-python3.10-pgcli-3.5.0/lib/python3.10/site-packages/pgcli/pgexecute.py", line 207, in connect\n    conn = psycopg.connect(conn_info)\n  File "/nix/store/cxfxzqrs01khsh6a2nlprfdikidnnffz-python3.10-psycopg-3.1.8/lib/python3.10/site-packages/psycopg/connection.py", line 728, in connect\n    raise ex.with_traceback(None)\npsycopg.OperationalError: connection failed: :1), port 7878 failed: FATAL:  password authentication failed for user "vini"\n'
2023-03-28 14:14:08,528 (72169/MainThread) pgcli.main INFO - Default pager found in PAGER environment variable: "less"
2023-03-28 14:14:13,798 (72169/MainThread) pgcli.main ERROR - traceback: 'Traceback (most recent call last):\n  File "/nix/store/wpq8iw12hx7xsblnqpqg7ihaysw73mcw-python3.10-pgcli-3.5.0/lib/python3.10/site-packages/pgcli/main.py", line 640, in connect\n    raise e\n  File "/nix/store/wpq8iw12hx7xsblnqpqg7ihaysw73mcw-python3.10-pgcli-3.5.0/lib/python3.10/site-packages/pgcli/main.py", line 627, in connect\n    pgexecute = PGExecute(database, user, passwd, host, port, dsn, **kwargs)\n  File "/nix/store/wpq8iw12hx7xsblnqpqg7ihaysw73mcw-python3.10-pgcli-3.5.0/lib/python3.10/site-packages/pgcli/pgexecute.py", line 161, in __init__\n    self.connect(database, user, password, host, port, dsn, **kwargs)\n  File "/nix/store/wpq8iw12hx7xsblnqpqg7ihaysw73mcw-python3.10-pgcli-3.5.0/lib/python3.10/site-packages/pgcli/pgexecute.py", line 207, in connect\n    conn = psycopg.connect(conn_info)\n  File "/nix/store/cxfxzqrs01khsh6a2nlprfdikidnnffz-python3.10-psycopg-3.1.8/lib/python3.10/site-packages/psycopg/connection.py", line 728, in connect\n    raise ex.with_traceback(None)\npsycopg.OperationalError: connection failed: :1), port 7878 failed: FATAL:  database "w12oHAXOoPjTQJM8cCcfRrRbtshR174R" does not exist\n'
2023-03-28 14:14:55,867 (72220/MainThread) pgcli.main INFO - Default pager found in PAGER environment variable: "less"
2023-03-28 14:15:51,840 (72220/MainThread) pgcli.pgexecute ERROR - sql: '\\dB', error: SyntaxError('syntax error at or near "\\"\nLINE 1: \\dB\n        ^')
2023-03-28 14:15:51,841 (72220/MainThread) pgcli.pgexecute ERROR - traceback: 'Traceback (most recent call last):\n  File "/nix/store/wpq8iw12hx7xsblnqpqg7ihaysw73mcw-python3.10-pgcli-3.5.0/lib/python3.10/site-packages/pgcli/pgexecute.py", line 373, in run\n    yield self.execute_normal_sql(sql) + (sql, True, False)\n  File "/nix/store/wpq8iw12hx7xsblnqpqg7ihaysw73mcw-python3.10-pgcli-3.5.0/lib/python3.10/site-packages/pgcli/pgexecute.py", line 423, in execute_normal_sql\n    cur.execute(split_sql)\n  File "/nix/store/wpq8iw12hx7xsblnqpqg7ihaysw73mcw-python3.10-pgcli-3.5.0/lib/python3.10/site-packages/pgcli/pgexecute.py", line 69, in execute\n    super().execute(*args, **kwargs)\n  File "/nix/store/cxfxzqrs01khsh6a2nlprfdikidnnffz-python3.10-psycopg-3.1.8/lib/python3.10/site-packages/psycopg/cursor.py", line 723, in execute\n    raise ex.with_traceback(None)\npsycopg.errors.SyntaxError: syntax error at or near "\\"\nLINE 1: \\dB\n        ^\n'
2023-03-28 14:20:25,382 (72220/MainThread) pgcli.pgexecute ERROR - sql: 'select id, experiment_key, flag_key, active, valid_from, valid_until from flink.price left join flink.pro  where experiment_key is not null', error: SyntaxError('syntax error at or near "where"\nLINE 1: ...valid_until from flink.price left join flink.pro  where expe...\n                                                             ^')
2023-03-28 14:20:25,383 (72220/MainThread) pgcli.pgexecute ERROR - traceback: 'Traceback (most recent call last):\n  File "/nix/store/wpq8iw12hx7xsblnqpqg7ihaysw73mcw-python3.10-pgcli-3.5.0/lib/python3.10/site-packages/pgcli/pgexecute.py", line 373, in run\n    yield self.execute_normal_sql(sql) + (sql, True, False)\n  File "/nix/store/wpq8iw12hx7xsblnqpqg7ihaysw73mcw-python3.10-pgcli-3.5.0/lib/python3.10/site-packages/pgcli/pgexecute.py", line 423, in execute_normal_sql\n    cur.execute(split_sql)\n  File "/nix/store/wpq8iw12hx7xsblnqpqg7ihaysw73mcw-python3.10-pgcli-3.5.0/lib/python3.10/site-packages/pgcli/pgexecute.py", line 69, in execute\n    super().execute(*args, **kwargs)\n  File "/nix/store/cxfxzqrs01khsh6a2nlprfdikidnnffz-python3.10-psycopg-3.1.8/lib/python3.10/site-packages/psycopg/cursor.py", line 723, in execute\n    raise ex.with_traceback(None)\npsycopg.errors.SyntaxError: syntax error at or near "where"\nLINE 1: ...valid_until from flink.price left join flink.pro  where expe...\n                                                             ^\n'
2023-03-28 14:21:08,314 (72220/MainThread) pgcli.pgexecute ERROR - sql: 'select id, experiment_key, flag_key, active, valid_from, valid_until from flink.price left join flink.product p where p.id = price.product_id  where experiment_key is not null', error: SyntaxError('syntax error at or near "where"\nLINE 1: ..._until from flink.price left join flink.product p where p.id...\n                                                             ^')
2023-03-28 14:21:08,315 (72220/MainThread) pgcli.pgexecute ERROR - traceback: 'Traceback (most recent call last):\n  File "/nix/store/wpq8iw12hx7xsblnqpqg7ihaysw73mcw-python3.10-pgcli-3.5.0/lib/python3.10/site-packages/pgcli/pgexecute.py", line 373, in run\n    yield self.execute_normal_sql(sql) + (sql, True, False)\n  File "/nix/store/wpq8iw12hx7xsblnqpqg7ihaysw73mcw-python3.10-pgcli-3.5.0/lib/python3.10/site-packages/pgcli/pgexecute.py", line 423, in execute_normal_sql\n    cur.execute(split_sql)\n  File "/nix/store/wpq8iw12hx7xsblnqpqg7ihaysw73mcw-python3.10-pgcli-3.5.0/lib/python3.10/site-packages/pgcli/pgexecute.py", line 69, in execute\n    super().execute(*args, **kwargs)\n  File "/nix/store/cxfxzqrs01khsh6a2nlprfdikidnnffz-python3.10-psycopg-3.1.8/lib/python3.10/site-packages/psycopg/cursor.py", line 723, in execute\n    raise ex.with_traceback(None)\npsycopg.errors.SyntaxError: syntax error at or near "where"\nLINE 1: ..._until from flink.price left join flink.product p where p.id...\n                                                             ^\n'
2023-03-28 14:26:40,754 (72220/MainThread) pgcli.pgexecute ERROR - sql: 'select id, experiment_key, flag_key, active, valid_from, valid_until from flink.price left join flink.product p on p.id = price.product_id where experiment_key is not null', error: AmbiguousColumn('column reference "id" is ambiguous\nLINE 1: select id, experiment_key, flag_key, active, valid_from, val...\n               ^')
2023-03-28 14:26:40,755 (72220/MainThread) pgcli.pgexecute ERROR - traceback: 'Traceback (most recent call last):\n  File "/nix/store/wpq8iw12hx7xsblnqpqg7ihaysw73mcw-python3.10-pgcli-3.5.0/lib/python3.10/site-packages/pgcli/pgexecute.py", line 373, in run\n    yield self.execute_normal_sql(sql) + (sql, True, False)\n  File "/nix/store/wpq8iw12hx7xsblnqpqg7ihaysw73mcw-python3.10-pgcli-3.5.0/lib/python3.10/site-packages/pgcli/pgexecute.py", line 423, in execute_normal_sql\n    cur.execute(split_sql)\n  File "/nix/store/wpq8iw12hx7xsblnqpqg7ihaysw73mcw-python3.10-pgcli-3.5.0/lib/python3.10/site-packages/pgcli/pgexecute.py", line 69, in execute\n    super().execute(*args, **kwargs)\n  File "/nix/store/cxfxzqrs01khsh6a2nlprfdikidnnffz-python3.10-psycopg-3.1.8/lib/python3.10/site-packages/psycopg/cursor.py", line 723, in execute\n    raise ex.with_traceback(None)\npsycopg.errors.AmbiguousColumn: column reference "id" is ambiguous\nLINE 1: select id, experiment_key, flag_key, active, valid_from, val...\n               ^\n'
2023-03-28 14:28:53,376 (72220/MainThread) pgcli.pgexecute ERROR - sql: 'select p.sku, experiment_key, flag_key, active, valid_from, valid_until from flink.price join flink.product p on p.id = price.product_id join flink.hub on hub.id = price.hub where experiment_key is not null', error: UndefinedColumn('column price.hub does not exist\nLINE 1: ....id = price.product_id join flink.hub on hub.id = price.hub ...\n                                                             ^')
2023-03-28 14:28:53,376 (72220/MainThread) pgcli.pgexecute ERROR - traceback: 'Traceback (most recent call last):\n  File "/nix/store/wpq8iw12hx7xsblnqpqg7ihaysw73mcw-python3.10-pgcli-3.5.0/lib/python3.10/site-packages/pgcli/pgexecute.py", line 373, in run\n    yield self.execute_normal_sql(sql) + (sql, True, False)\n  File "/nix/store/wpq8iw12hx7xsblnqpqg7ihaysw73mcw-python3.10-pgcli-3.5.0/lib/python3.10/site-packages/pgcli/pgexecute.py", line 423, in execute_normal_sql\n    cur.execute(split_sql)\n  File "/nix/store/wpq8iw12hx7xsblnqpqg7ihaysw73mcw-python3.10-pgcli-3.5.0/lib/python3.10/site-packages/pgcli/pgexecute.py", line 69, in execute\n    super().execute(*args, **kwargs)\n  File "/nix/store/cxfxzqrs01khsh6a2nlprfdikidnnffz-python3.10-psycopg-3.1.8/lib/python3.10/site-packages/psycopg/cursor.py", line 723, in execute\n    raise ex.with_traceback(None)\npsycopg.errors.UndefinedColumn: column price.hub does not exist\nLINE 1: ....id = price.product_id join flink.hub on hub.id = price.hub ...\n                                                             ^\n'
2023-03-28 14:37:45,427 (72220/MainThread) pgcli.pgexecute ERROR - sql: "select p.sku, hub.slug, experiment_key, flag_key, vara from flink.price join flink.product p on p.id = price.product_id join flink.hub on hub.id = price.hub_id where experiment_key is not null and hub.slug = 'de_ber_alex'", error: UndefinedColumn('column "vara" does not exist\nLINE 1: select p.sku, hub.slug, experiment_key, flag_key, vara from ...\n                                                          ^')
2023-03-28 14:37:45,427 (72220/MainThread) pgcli.pgexecute ERROR - traceback: 'Traceback (most recent call last):\n  File "/nix/store/wpq8iw12hx7xsblnqpqg7ihaysw73mcw-python3.10-pgcli-3.5.0/lib/python3.10/site-packages/pgcli/pgexecute.py", line 373, in run\n    yield self.execute_normal_sql(sql) + (sql, True, False)\n  File "/nix/store/wpq8iw12hx7xsblnqpqg7ihaysw73mcw-python3.10-pgcli-3.5.0/lib/python3.10/site-packages/pgcli/pgexecute.py", line 423, in execute_normal_sql\n    cur.execute(split_sql)\n  File "/nix/store/wpq8iw12hx7xsblnqpqg7ihaysw73mcw-python3.10-pgcli-3.5.0/lib/python3.10/site-packages/pgcli/pgexecute.py", line 69, in execute\n    super().execute(*args, **kwargs)\n  File "/nix/store/cxfxzqrs01khsh6a2nlprfdikidnnffz-python3.10-psycopg-3.1.8/lib/python3.10/site-packages/psycopg/cursor.py", line 723, in execute\n    raise ex.with_traceback(None)\npsycopg.errors.UndefinedColumn: column "vara" does not exist\nLINE 1: select p.sku, hub.slug, experiment_key, flag_key, vara from ...\n                                                          ^\n'
2023-03-28 14:39:15,454 (73802/MainThread) pgcli.main INFO - Default pager found in PAGER environment variable: "less"
2023-03-28 14:39:43,607 (73840/MainThread) pgcli.main INFO - Default pager found in PAGER environment variable: "less"
2023-03-28 14:40:23,707 (73840/MainThread) pgcli.pgexecute ERROR - sql: "select p.sku, hub.slug, experiment_key, flag_key, price.variat from flink.price join flink.product p on p.id = price.product_id join flink.hub on hub.id = price.hub_id where experiment_key is not null and hub.slug = 'de_ber_alex'", error: UndefinedColumn('column price.variat does not exist\nLINE 1: select p.sku, hub.slug, experiment_key, flag_key, price.vari...\n                                                          ^')
2023-03-28 14:40:23,710 (73840/MainThread) pgcli.pgexecute ERROR - traceback: 'Traceback (most recent call last):\n  File "/nix/store/wpq8iw12hx7xsblnqpqg7ihaysw73mcw-python3.10-pgcli-3.5.0/lib/python3.10/site-packages/pgcli/pgexecute.py", line 373, in run\n    yield self.execute_normal_sql(sql) + (sql, True, False)\n  File "/nix/store/wpq8iw12hx7xsblnqpqg7ihaysw73mcw-python3.10-pgcli-3.5.0/lib/python3.10/site-packages/pgcli/pgexecute.py", line 423, in execute_normal_sql\n    cur.execute(split_sql)\n  File "/nix/store/wpq8iw12hx7xsblnqpqg7ihaysw73mcw-python3.10-pgcli-3.5.0/lib/python3.10/site-packages/pgcli/pgexecute.py", line 69, in execute\n    super().execute(*args, **kwargs)\n  File "/nix/store/cxfxzqrs01khsh6a2nlprfdikidnnffz-python3.10-psycopg-3.1.8/lib/python3.10/site-packages/psycopg/cursor.py", line 723, in execute\n    raise ex.with_traceback(None)\npsycopg.errors.UndefinedColumn: column price.variat does not exist\nLINE 1: select p.sku, hub.slug, experiment_key, flag_key, price.vari...\n                                                          ^\n'
2023-03-28 15:25:17,824 (79125/MainThread) pgcli.main INFO - Default pager found in PAGER environment variable: "less"
2023-03-29 16:11:43,870 (49146/MainThread) pgcli.main INFO - Default pager found in PAGER environment variable: "less"
2023-04-12 18:17:31,564 (11578/MainThread) pgcli.main INFO - Default pager found in PAGER environment variable: "less"
2023-04-12 18:17:33,752 (11578/MainThread) pgcli.main ERROR - traceback: 'Traceback (most recent call last):\n  File "/nix/store/wpq8iw12hx7xsblnqpqg7ihaysw73mcw-python3.10-pgcli-3.5.0/lib/python3.10/site-packages/pgcli/main.py", line 640, in connect\n    raise e\n  File "/nix/store/wpq8iw12hx7xsblnqpqg7ihaysw73mcw-python3.10-pgcli-3.5.0/lib/python3.10/site-packages/pgcli/main.py", line 627, in connect\n    pgexecute = PGExecute(database, user, passwd, host, port, dsn, **kwargs)\n  File "/nix/store/wpq8iw12hx7xsblnqpqg7ihaysw73mcw-python3.10-pgcli-3.5.0/lib/python3.10/site-packages/pgcli/pgexecute.py", line 161, in __init__\n    self.connect(database, user, password, host, port, dsn, **kwargs)\n  File "/nix/store/wpq8iw12hx7xsblnqpqg7ihaysw73mcw-python3.10-pgcli-3.5.0/lib/python3.10/site-packages/pgcli/pgexecute.py", line 207, in connect\n    conn = psycopg.connect(conn_info)\n  File "/nix/store/cxfxzqrs01khsh6a2nlprfdikidnnffz-python3.10-psycopg-3.1.8/lib/python3.10/site-packages/psycopg/connection.py", line 728, in connect\n    raise ex.with_traceback(None)\npsycopg.OperationalError: connection failed: :1), port 7878 failed: FATAL:  database "w12oHAXOoPjTQJM8cCcfRrRbtshR174R" does not exist\n'
2023-04-12 18:17:42,050 (11616/MainThread) pgcli.main INFO - Default pager found in PAGER environment variable: "less"
2023-04-12 18:17:43,436 (11616/MainThread) pgcli.main ERROR - traceback: 'Traceback (most recent call last):\n  File "/nix/store/wpq8iw12hx7xsblnqpqg7ihaysw73mcw-python3.10-pgcli-3.5.0/lib/python3.10/site-packages/pgcli/main.py", line 640, in connect\n    raise e\n  File "/nix/store/wpq8iw12hx7xsblnqpqg7ihaysw73mcw-python3.10-pgcli-3.5.0/lib/python3.10/site-packages/pgcli/main.py", line 627, in connect\n    pgexecute = PGExecute(database, user, passwd, host, port, dsn, **kwargs)\n  File "/nix/store/wpq8iw12hx7xsblnqpqg7ihaysw73mcw-python3.10-pgcli-3.5.0/lib/python3.10/site-packages/pgcli/pgexecute.py", line 161, in __init__\n    self.connect(database, user, password, host, port, dsn, **kwargs)\n  File "/nix/store/wpq8iw12hx7xsblnqpqg7ihaysw73mcw-python3.10-pgcli-3.5.0/lib/python3.10/site-packages/pgcli/pgexecute.py", line 207, in connect\n    conn = psycopg.connect(conn_info)\n  File "/nix/store/cxfxzqrs01khsh6a2nlprfdikidnnffz-python3.10-psycopg-3.1.8/lib/python3.10/site-packages/psycopg/connection.py", line 728, in connect\n    raise ex.with_traceback(None)\npsycopg.OperationalError: connection failed: :1), port 7878 failed: FATAL:  database "kubernetes" does not exist\n'
2023-04-12 18:18:02,886 (11668/MainThread) pgcli.main INFO - Default pager found in PAGER environment variable: "less"
2023-04-12 20:41:49,904 (11668/MainThread) pgcli.pgexecute ERROR - sql: "select p.sku, hub.slug, experiment_key, flag_key, price.variation_key, price.base_cent_amount from flink.price join flink.product p on p.id = price.product_id join flink.hub on hub.id = price.hub_id where  hub.slug = 'de_ham_wand'", error: OperationalError('sending query failed: server closed the connection unexpectedly\n\tThis probably means the server terminated abnormally\n\tbefore or while processing the request.')
2023-04-12 20:41:49,910 (11668/MainThread) pgcli.pgexecute ERROR - traceback: 'Traceback (most recent call last):\n  File "/nix/store/wpq8iw12hx7xsblnqpqg7ihaysw73mcw-python3.10-pgcli-3.5.0/lib/python3.10/site-packages/pgcli/pgexecute.py", line 373, in run\n    yield self.execute_normal_sql(sql) + (sql, True, False)\n  File "/nix/store/wpq8iw12hx7xsblnqpqg7ihaysw73mcw-python3.10-pgcli-3.5.0/lib/python3.10/site-packages/pgcli/pgexecute.py", line 423, in execute_normal_sql\n    cur.execute(split_sql)\n  File "/nix/store/wpq8iw12hx7xsblnqpqg7ihaysw73mcw-python3.10-pgcli-3.5.0/lib/python3.10/site-packages/pgcli/pgexecute.py", line 69, in execute\n    super().execute(*args, **kwargs)\n  File "/nix/store/cxfxzqrs01khsh6a2nlprfdikidnnffz-python3.10-psycopg-3.1.8/lib/python3.10/site-packages/psycopg/cursor.py", line 723, in execute\n    raise ex.with_traceback(None)\npsycopg.OperationalError: sending query failed: server closed the connection unexpectedly\n\tThis probably means the server terminated abnormally\n\tbefore or while processing the request.\n'
2023-04-12 20:41:49,910 (11668/MainThread) pgcli.main ERROR - sql: "select p.sku, hub.slug, experiment_key, flag_key, price.variation_key, price.base_cent_amount from flink.price join flink.product p on p.id = price.product_id join flink.hub on hub.id = price.hub_id where  hub.slug = 'de_ham_wand';", error: OperationalError('sending query failed: server closed the connection unexpectedly\n\tThis probably means the server terminated abnormally\n\tbefore or while processing the request.')
2023-04-12 20:41:49,911 (11668/MainThread) pgcli.main ERROR - traceback: 'Traceback (most recent call last):\n  File "/nix/store/wpq8iw12hx7xsblnqpqg7ihaysw73mcw-python3.10-pgcli-3.5.0/lib/python3.10/site-packages/pgcli/main.py", line 705, in execute_command\n    output, query = self._evaluate_command(text)\n  File "/nix/store/wpq8iw12hx7xsblnqpqg7ihaysw73mcw-python3.10-pgcli-3.5.0/lib/python3.10/site-packages/pgcli/main.py", line 972, in _evaluate_command\n    for title, cur, headers, status, sql, success, is_special in res:\n  File "/nix/store/wpq8iw12hx7xsblnqpqg7ihaysw73mcw-python3.10-pgcli-3.5.0/lib/python3.10/site-packages/pgcli/pgexecute.py", line 373, in run\n    yield self.execute_normal_sql(sql) + (sql, True, False)\n  File "/nix/store/wpq8iw12hx7xsblnqpqg7ihaysw73mcw-python3.10-pgcli-3.5.0/lib/python3.10/site-packages/pgcli/pgexecute.py", line 423, in execute_normal_sql\n    cur.execute(split_sql)\n  File "/nix/store/wpq8iw12hx7xsblnqpqg7ihaysw73mcw-python3.10-pgcli-3.5.0/lib/python3.10/site-packages/pgcli/pgexecute.py", line 69, in execute\n    super().execute(*args, **kwargs)\n  File "/nix/store/cxfxzqrs01khsh6a2nlprfdikidnnffz-python3.10-psycopg-3.1.8/lib/python3.10/site-packages/psycopg/cursor.py", line 723, in execute\n    raise ex.with_traceback(None)\npsycopg.OperationalError: sending query failed: server closed the connection unexpectedly\n\tThis probably means the server terminated abnormally\n\tbefore or while processing the request.\n'
2023-04-13 16:47:14,624 (11668/MainThread) pgcli.pgexecute ERROR - sql: "select p.sku, price.base_cent_amount from flink.price join flink.product p on p.id = price.product_id join flink.hub on hub.id = price.hub_id where  hub.slug = 'de_ham_wand'", error: OperationalError('sending query failed: server closed the connection unexpectedly\n\tThis probably means the server terminated abnormally\n\tbefore or while processing the request.')
2023-04-13 16:47:14,627 (11668/MainThread) pgcli.pgexecute ERROR - traceback: 'Traceback (most recent call last):\n  File "/nix/store/wpq8iw12hx7xsblnqpqg7ihaysw73mcw-python3.10-pgcli-3.5.0/lib/python3.10/site-packages/pgcli/pgexecute.py", line 373, in run\n    yield self.execute_normal_sql(sql) + (sql, True, False)\n  File "/nix/store/wpq8iw12hx7xsblnqpqg7ihaysw73mcw-python3.10-pgcli-3.5.0/lib/python3.10/site-packages/pgcli/pgexecute.py", line 423, in execute_normal_sql\n    cur.execute(split_sql)\n  File "/nix/store/wpq8iw12hx7xsblnqpqg7ihaysw73mcw-python3.10-pgcli-3.5.0/lib/python3.10/site-packages/pgcli/pgexecute.py", line 69, in execute\n    super().execute(*args, **kwargs)\n  File "/nix/store/cxfxzqrs01khsh6a2nlprfdikidnnffz-python3.10-psycopg-3.1.8/lib/python3.10/site-packages/psycopg/cursor.py", line 723, in execute\n    raise ex.with_traceback(None)\npsycopg.OperationalError: sending query failed: server closed the connection unexpectedly\n\tThis probably means the server terminated abnormally\n\tbefore or while processing the request.\n'
2023-04-13 16:47:14,627 (11668/MainThread) pgcli.main ERROR - sql: "select p.sku, price.base_cent_amount from flink.price join flink.product p on p.id = price.product_id join flink.hub on hub.id = price.hub_id where  hub.slug = 'de_ham_wand';", error: OperationalError('sending query failed: server closed the connection unexpectedly\n\tThis probably means the server terminated abnormally\n\tbefore or while processing the request.')
2023-04-13 16:47:14,627 (11668/MainThread) pgcli.main ERROR - traceback: 'Traceback (most recent call last):\n  File "/nix/store/wpq8iw12hx7xsblnqpqg7ihaysw73mcw-python3.10-pgcli-3.5.0/lib/python3.10/site-packages/pgcli/main.py", line 705, in execute_command\n    output, query = self._evaluate_command(text)\n  File "/nix/store/wpq8iw12hx7xsblnqpqg7ihaysw73mcw-python3.10-pgcli-3.5.0/lib/python3.10/site-packages/pgcli/main.py", line 972, in _evaluate_command\n    for title, cur, headers, status, sql, success, is_special in res:\n  File "/nix/store/wpq8iw12hx7xsblnqpqg7ihaysw73mcw-python3.10-pgcli-3.5.0/lib/python3.10/site-packages/pgcli/pgexecute.py", line 373, in run\n    yield self.execute_normal_sql(sql) + (sql, True, False)\n  File "/nix/store/wpq8iw12hx7xsblnqpqg7ihaysw73mcw-python3.10-pgcli-3.5.0/lib/python3.10/site-packages/pgcli/pgexecute.py", line 423, in execute_normal_sql\n    cur.execute(split_sql)\n  File "/nix/store/wpq8iw12hx7xsblnqpqg7ihaysw73mcw-python3.10-pgcli-3.5.0/lib/python3.10/site-packages/pgcli/pgexecute.py", line 69, in execute\n    super().execute(*args, **kwargs)\n  File "/nix/store/cxfxzqrs01khsh6a2nlprfdikidnnffz-python3.10-psycopg-3.1.8/lib/python3.10/site-packages/psycopg/cursor.py", line 723, in execute\n    raise ex.with_traceback(None)\npsycopg.OperationalError: sending query failed: server closed the connection unexpectedly\n\tThis probably means the server terminated abnormally\n\tbefore or while processing the request.\n'
2023-04-13 16:47:16,920 (11668/MainThread) pgcli.pgexecute ERROR - sql: "select p.sku, price.base_cent_amount from flink.price join flink.product p on p.id = price.product_id join flink.hub on hub.id = price.hub_id where  hub.slug = 'de_ham_wand'", error: OperationalError('the connection is closed')
2023-04-13 16:47:16,922 (11668/MainThread) pgcli.pgexecute ERROR - traceback: 'Traceback (most recent call last):\n  File "/nix/store/wpq8iw12hx7xsblnqpqg7ihaysw73mcw-python3.10-pgcli-3.5.0/lib/python3.10/site-packages/pgcli/pgexecute.py", line 349, in run\n    cur = self.conn.cursor()\n  File "/nix/store/cxfxzqrs01khsh6a2nlprfdikidnnffz-python3.10-psycopg-3.1.8/lib/python3.10/site-packages/psycopg/connection.py", line 840, in cursor\n    self._check_connection_ok()\n  File "/nix/store/cxfxzqrs01khsh6a2nlprfdikidnnffz-python3.10-psycopg-3.1.8/lib/python3.10/site-packages/psycopg/connection.py", line 479, in _check_connection_ok\n    raise e.OperationalError("the connection is closed")\npsycopg.OperationalError: the connection is closed\n'
2023-04-13 16:47:16,922 (11668/MainThread) pgcli.main ERROR - sql: "select p.sku, price.base_cent_amount from flink.price join flink.product p on p.id = price.product_id join flink.hub on hub.id = price.hub_id where  hub.slug = 'de_ham_wand';", error: OperationalError('the connection is closed')
2023-04-13 16:47:16,922 (11668/MainThread) pgcli.main ERROR - traceback: 'Traceback (most recent call last):\n  File "/nix/store/wpq8iw12hx7xsblnqpqg7ihaysw73mcw-python3.10-pgcli-3.5.0/lib/python3.10/site-packages/pgcli/main.py", line 705, in execute_command\n    output, query = self._evaluate_command(text)\n  File "/nix/store/wpq8iw12hx7xsblnqpqg7ihaysw73mcw-python3.10-pgcli-3.5.0/lib/python3.10/site-packages/pgcli/main.py", line 972, in _evaluate_command\n    for title, cur, headers, status, sql, success, is_special in res:\n  File "/nix/store/wpq8iw12hx7xsblnqpqg7ihaysw73mcw-python3.10-pgcli-3.5.0/lib/python3.10/site-packages/pgcli/pgexecute.py", line 349, in run\n    cur = self.conn.cursor()\n  File "/nix/store/cxfxzqrs01khsh6a2nlprfdikidnnffz-python3.10-psycopg-3.1.8/lib/python3.10/site-packages/psycopg/connection.py", line 840, in cursor\n    self._check_connection_ok()\n  File "/nix/store/cxfxzqrs01khsh6a2nlprfdikidnnffz-python3.10-psycopg-3.1.8/lib/python3.10/site-packages/psycopg/connection.py", line 479, in _check_connection_ok\n    raise e.OperationalError("the connection is closed")\npsycopg.OperationalError: the connection is closed\n'
2023-04-20 17:07:58,649 (43207/MainThread) pgcli.main INFO - Default pager found in PAGER environment variable: "less"
2023-04-20 17:07:59,261 (43207/MainThread) pgcli.main ERROR - traceback: 'Traceback (most recent call last):\n  File "/nix/store/wpq8iw12hx7xsblnqpqg7ihaysw73mcw-python3.10-pgcli-3.5.0/lib/python3.10/site-packages/pgcli/main.py", line 640, in connect\n    raise e\n  File "/nix/store/wpq8iw12hx7xsblnqpqg7ihaysw73mcw-python3.10-pgcli-3.5.0/lib/python3.10/site-packages/pgcli/main.py", line 627, in connect\n    pgexecute = PGExecute(database, user, passwd, host, port, dsn, **kwargs)\n  File "/nix/store/wpq8iw12hx7xsblnqpqg7ihaysw73mcw-python3.10-pgcli-3.5.0/lib/python3.10/site-packages/pgcli/pgexecute.py", line 161, in __init__\n    self.connect(database, user, password, host, port, dsn, **kwargs)\n  File "/nix/store/wpq8iw12hx7xsblnqpqg7ihaysw73mcw-python3.10-pgcli-3.5.0/lib/python3.10/site-packages/pgcli/pgexecute.py", line 207, in connect\n    conn = psycopg.connect(conn_info)\n  File "/nix/store/cxfxzqrs01khsh6a2nlprfdikidnnffz-python3.10-psycopg-3.1.8/lib/python3.10/site-packages/psycopg/connection.py", line 728, in connect\n    raise ex.with_traceback(None)\npsycopg.OperationalError: connection failed: :1), port 7878 failed: FATAL:  database "kubernetes" does not exist\n'
2023-04-20 17:08:05,160 (43233/MainThread) pgcli.main INFO - Default pager found in PAGER environment variable: "less"
2023-04-20 17:08:09,481 (43233/MainThread) pgcli.main ERROR - traceback: 'Traceback (most recent call last):\n  File "/nix/store/wpq8iw12hx7xsblnqpqg7ihaysw73mcw-python3.10-pgcli-3.5.0/lib/python3.10/site-packages/pgcli/main.py", line 630, in connect\n    passwd = click.prompt(\n  File "/nix/store/92xdj9gl9axxy44179vg59ym0xdrpl9a-python3.10-click-8.1.3/lib/python3.10/site-packages/click/termui.py", line 166, in prompt\n    value = prompt_func(prompt)\n  File "/nix/store/92xdj9gl9axxy44179vg59ym0xdrpl9a-python3.10-click-8.1.3/lib/python3.10/site-packages/click/termui.py", line 149, in prompt_func\n    raise Abort() from None\nclick.exceptions.Abort\n'
2023-04-20 17:08:22,682 (43264/MainThread) pgcli.main INFO - Default pager found in PAGER environment variable: "less"
2023-05-08 12:47:41,036 (45095/MainThread) pgcli.main INFO - Default pager found in PAGER environment variable: "less"
2023-05-08 12:47:41,079 (45095/MainThread) pgcli.main ERROR - traceback: 'Traceback (most recent call last):\n  File "/nix/store/wpq8iw12hx7xsblnqpqg7ihaysw73mcw-python3.10-pgcli-3.5.0/lib/python3.10/site-packages/pgcli/main.py", line 640, in connect\n    raise e\n  File "/nix/store/wpq8iw12hx7xsblnqpqg7ihaysw73mcw-python3.10-pgcli-3.5.0/lib/python3.10/site-packages/pgcli/main.py", line 627, in connect\n    pgexecute = PGExecute(database, user, passwd, host, port, dsn, **kwargs)\n  File "/nix/store/wpq8iw12hx7xsblnqpqg7ihaysw73mcw-python3.10-pgcli-3.5.0/lib/python3.10/site-packages/pgcli/pgexecute.py", line 161, in __init__\n    self.connect(database, user, password, host, port, dsn, **kwargs)\n  File "/nix/store/wpq8iw12hx7xsblnqpqg7ihaysw73mcw-python3.10-pgcli-3.5.0/lib/python3.10/site-packages/pgcli/pgexecute.py", line 207, in connect\n    conn = psycopg.connect(conn_info)\n  File "/nix/store/cxfxzqrs01khsh6a2nlprfdikidnnffz-python3.10-psycopg-3.1.8/lib/python3.10/site-packages/psycopg/connection.py", line 728, in connect\n    raise ex.with_traceback(None)\npsycopg.OperationalError: connection is bad: No such file or directory\n\tIs the server running locally and accepting connections on that socket?\n'
2023-05-08 12:48:38,751 (45230/MainThread) pgcli.main INFO - Default pager found in PAGER environment variable: "less"
2023-05-08 12:48:42,264 (45230/MainThread) pgcli.pgexecute ERROR - sql: 'l', error: SyntaxError('syntax error at or near "l"\nLINE 1: l\n        ^')
2023-05-08 12:48:42,265 (45230/MainThread) pgcli.pgexecute ERROR - traceback: 'Traceback (most recent call last):\n  File "/nix/store/wpq8iw12hx7xsblnqpqg7ihaysw73mcw-python3.10-pgcli-3.5.0/lib/python3.10/site-packages/pgcli/pgexecute.py", line 373, in run\n    yield self.execute_normal_sql(sql) + (sql, True, False)\n  File "/nix/store/wpq8iw12hx7xsblnqpqg7ihaysw73mcw-python3.10-pgcli-3.5.0/lib/python3.10/site-packages/pgcli/pgexecute.py", line 423, in execute_normal_sql\n    cur.execute(split_sql)\n  File "/nix/store/wpq8iw12hx7xsblnqpqg7ihaysw73mcw-python3.10-pgcli-3.5.0/lib/python3.10/site-packages/pgcli/pgexecute.py", line 69, in execute\n    super().execute(*args, **kwargs)\n  File "/nix/store/cxfxzqrs01khsh6a2nlprfdikidnnffz-python3.10-psycopg-3.1.8/lib/python3.10/site-packages/psycopg/cursor.py", line 723, in execute\n    raise ex.with_traceback(None)\npsycopg.errors.SyntaxError: syntax error at or near "l"\nLINE 1: l\n        ^\n'
2023-05-08 14:13:36,201 (45230/MainThread) pgcli.pgexecute ERROR - sql: 'clear', error: SyntaxError('syntax error at or near "clear"\nLINE 1: clear\n        ^')
2023-05-08 14:13:36,202 (45230/MainThread) pgcli.pgexecute ERROR - traceback: 'Traceback (most recent call last):\n  File "/nix/store/wpq8iw12hx7xsblnqpqg7ihaysw73mcw-python3.10-pgcli-3.5.0/lib/python3.10/site-packages/pgcli/pgexecute.py", line 373, in run\n    yield self.execute_normal_sql(sql) + (sql, True, False)\n  File "/nix/store/wpq8iw12hx7xsblnqpqg7ihaysw73mcw-python3.10-pgcli-3.5.0/lib/python3.10/site-packages/pgcli/pgexecute.py", line 423, in execute_normal_sql\n    cur.execute(split_sql)\n  File "/nix/store/wpq8iw12hx7xsblnqpqg7ihaysw73mcw-python3.10-pgcli-3.5.0/lib/python3.10/site-packages/pgcli/pgexecute.py", line 69, in execute\n    super().execute(*args, **kwargs)\n  File "/nix/store/cxfxzqrs01khsh6a2nlprfdikidnnffz-python3.10-psycopg-3.1.8/lib/python3.10/site-packages/psycopg/cursor.py", line 723, in execute\n    raise ex.with_traceback(None)\npsycopg.errors.SyntaxError: syntax error at or near "clear"\nLINE 1: clear\n        ^\n'
2023-05-08 14:14:43,119 (45230/MainThread) pgcli.pgexecute ERROR - sql: 'CLEAR', error: SyntaxError('syntax error at or near "CLEAR"\nLINE 1: CLEAR\n        ^')
2023-05-08 14:14:43,120 (45230/MainThread) pgcli.pgexecute ERROR - traceback: 'Traceback (most recent call last):\n  File "/nix/store/wpq8iw12hx7xsblnqpqg7ihaysw73mcw-python3.10-pgcli-3.5.0/lib/python3.10/site-packages/pgcli/pgexecute.py", line 373, in run\n    yield self.execute_normal_sql(sql) + (sql, True, False)\n  File "/nix/store/wpq8iw12hx7xsblnqpqg7ihaysw73mcw-python3.10-pgcli-3.5.0/lib/python3.10/site-packages/pgcli/pgexecute.py", line 423, in execute_normal_sql\n    cur.execute(split_sql)\n  File "/nix/store/wpq8iw12hx7xsblnqpqg7ihaysw73mcw-python3.10-pgcli-3.5.0/lib/python3.10/site-packages/pgcli/pgexecute.py", line 69, in execute\n    super().execute(*args, **kwargs)\n  File "/nix/store/cxfxzqrs01khsh6a2nlprfdikidnnffz-python3.10-psycopg-3.1.8/lib/python3.10/site-packages/psycopg/cursor.py", line 723, in execute\n    raise ex.with_traceback(None)\npsycopg.errors.SyntaxError: syntax error at or near "CLEAR"\nLINE 1: CLEAR\n        ^\n'
2023-05-08 14:14:44,976 (45230/MainThread) pgcli.pgexecute ERROR - sql: 'clear', error: SyntaxError('syntax error at or near "clear"\nLINE 1: clear\n        ^')
2023-05-08 14:14:44,976 (45230/MainThread) pgcli.pgexecute ERROR - traceback: 'Traceback (most recent call last):\n  File "/nix/store/wpq8iw12hx7xsblnqpqg7ihaysw73mcw-python3.10-pgcli-3.5.0/lib/python3.10/site-packages/pgcli/pgexecute.py", line 373, in run\n    yield self.execute_normal_sql(sql) + (sql, True, False)\n  File "/nix/store/wpq8iw12hx7xsblnqpqg7ihaysw73mcw-python3.10-pgcli-3.5.0/lib/python3.10/site-packages/pgcli/pgexecute.py", line 423, in execute_normal_sql\n    cur.execute(split_sql)\n  File "/nix/store/wpq8iw12hx7xsblnqpqg7ihaysw73mcw-python3.10-pgcli-3.5.0/lib/python3.10/site-packages/pgcli/pgexecute.py", line 69, in execute\n    super().execute(*args, **kwargs)\n  File "/nix/store/cxfxzqrs01khsh6a2nlprfdikidnnffz-python3.10-psycopg-3.1.8/lib/python3.10/site-packages/psycopg/cursor.py", line 723, in execute\n    raise ex.with_traceback(None)\npsycopg.errors.SyntaxError: syntax error at or near "clear"\nLINE 1: clear\n        ^\n'
